<?xml version="1.0"?>
<robot name="my_diffbot">

  <!-- 颜色定义 -->
  <material name="gray"><color rgba="0.6 0.6 0.6 1.0"/></material>
  <material name="black"><color rgba="0 0 0 1.0"/></material>
  <material name="red"><color rgba="0.8 0.2 0.2 1.0"/></material>

  <!-- 基准 link -->

  <!-- 底盘 -->
  <link name="base_link">
    <inertial>
      <mass value="8.0"/>
      <origin xyz="0 0 0" rpy="0 0 0"/>
      <inertia ixx="0.1" ixy="0" ixz="0" iyy="0.1" iyz="0" izz="0.1"/>
    </inertial>

    <visual>
      <geometry><box size="0.5 0.35 0.1"/></geometry>
      <material name="gray"/>
    </visual>

    <collision>
      <geometry><box size="0.5 0.35 0.1"/></geometry>
    </collision>
  </link>

  <!-- 左轮 -->
  <link name="left_wheel">
    <visual>
      <origin xyz="0 0 0" rpy="1.5708 0 0"/>
      <geometry>
        <cylinder length="0.05" radius="0.07"/>
      </geometry>
      <material name="black"/>
    </visual>

    <collision>
      <origin xyz="0 0 0" rpy="1.5708 0 0"/>
      <geometry>
        <cylinder length="0.05" radius="0.07"/>
      </geometry>
    </collision>
  </link>

  <joint name="left_wheel_joint" type="continuous">
    <parent link="base_link"/>
    <child link="left_wheel"/>
    <origin xyz="0.12 0.17 -0.035" rpy="0 0 0"/>
    <axis xyz="0 1 0"/>
  </joint>

  <!-- 右轮 -->
  <link name="right_wheel">
    <visual>
      <origin xyz="0 0 0" rpy="1.5708 0 0"/>
      <geometry>
        <cylinder length="0.05" radius="0.07"/>
      </geometry>
      <material name="black"/>
    </visual>

    <collision>
      <origin xyz="0 0 0" rpy="1.5708 0 0"/>
      <geometry>
        <cylinder length="0.05" radius="0.07"/>
      </geometry>
    </collision>
  </link>

  <joint name="right_wheel_joint" type="continuous">
    <parent link="base_link"/>
    <child link="right_wheel"/>
    <origin xyz="0.12 -0.17 -0.035" rpy="0 0 0"/>
    <axis xyz="0 1 0"/>
  </joint>

<!-- 支撑轮（caster）-->
  <link name="caster">
    <!-- 外观 -->
    <visual>
      <origin xyz="0 0 0" rpy="0 0 0"/>
      <geometry>
        <sphere radius="0.03"/>
      </geometry>
      <material name="black"/>
    </visual>

    <!-- 碰撞体 -->
    <collision>
      <origin xyz="0 0 0" rpy="0 0 0"/>
      <geometry>
        <sphere radius="0.03"/>
      </geometry>
    </collision>
  </link>

  <!-- 固定连接到底盘尾部偏下方 -->
  <joint name="caster_joint" type="fixed">
    <parent link="base_link"/>
    <child link="caster"/>
    <origin xyz="-0.18 0.0 -0.075" rpy="0 0 0"/>
  </joint>

  <!-- 激光雷达 -->
  <link name="lidar_link">
    <visual>
      <geometry><cylinder length="0.04" radius="0.03"/></geometry>
      <material name="red"/>
    </visual>
  </link>

  <joint name="lidar_joint" type="fixed">
    <parent link="base_link"/>
    <child link="lidar_link"/>
    <origin xyz="0.18 0.0 0.08" rpy="0 0 0"/>
  </joint>

</robot>
